[2021-05-17 07:19:57,901] {taskinstance.py:851} INFO - Dependencies all met for <TaskInstance: etl_postgresql2mongo.read_table_as_DF 2021-05-17T07:10:00+00:00 [queued]>
[2021-05-17 07:19:57,920] {taskinstance.py:851} INFO - Dependencies all met for <TaskInstance: etl_postgresql2mongo.read_table_as_DF 2021-05-17T07:10:00+00:00 [queued]>
[2021-05-17 07:19:57,920] {taskinstance.py:1042} INFO - 
--------------------------------------------------------------------------------
[2021-05-17 07:19:57,920] {taskinstance.py:1043} INFO - Starting attempt 1 of 1
[2021-05-17 07:19:57,921] {taskinstance.py:1044} INFO - 
--------------------------------------------------------------------------------
[2021-05-17 07:19:57,941] {taskinstance.py:1063} INFO - Executing <Task(PythonOperator): read_table_as_DF> on 2021-05-17T07:10:00+00:00
[2021-05-17 07:19:57,947] {standard_task_runner.py:52} INFO - Started process 94 to run task
[2021-05-17 07:19:57,952] {standard_task_runner.py:76} INFO - Running: ['airflow', 'tasks', 'run', 'etl_postgresql2mongo', 'read_table_as_DF', '2021-05-17T07:10:00+00:00', '--job-id', '17', '--pool', 'default_pool', '--raw', '--subdir', 'DAGS_FOLDER/csv_postgres_2_mongo.py', '--cfg-path', '/tmp/tmpm5ykh9_z', '--error-file', '/tmp/tmpe4m8uilm']
[2021-05-17 07:19:57,952] {standard_task_runner.py:77} INFO - Job 17: Subtask read_table_as_DF
[2021-05-17 07:19:58,015] {logging_mixin.py:104} INFO - Running <TaskInstance: etl_postgresql2mongo.read_table_as_DF 2021-05-17T07:10:00+00:00 [running]> on host d0d96188f4f7
[2021-05-17 07:19:58,076] {taskinstance.py:1257} INFO - Exporting the following env vars:
AIRFLOW_CTX_DAG_OWNER=airflow
AIRFLOW_CTX_DAG_ID=etl_postgresql2mongo
AIRFLOW_CTX_TASK_ID=read_table_as_DF
AIRFLOW_CTX_EXECUTION_DATE=2021-05-17T07:10:00+00:00
AIRFLOW_CTX_DAG_RUN_ID=scheduled__2021-05-17T07:10:00+00:00
[2021-05-17 07:19:58,085] {taskinstance.py:1455} ERROR - (psycopg2.OperationalError) FATAL:  database "csv_data" does not exist

(Background on this error at: http://sqlalche.me/e/13/e3q8)
Traceback (most recent call last):
  File "/home/airflow/.local/lib/python3.6/site-packages/sqlalchemy/engine/base.py", line 2336, in _wrap_pool_connect
    return fn()
  File "/home/airflow/.local/lib/python3.6/site-packages/sqlalchemy/pool/base.py", line 364, in connect
    return _ConnectionFairy._checkout(self)
  File "/home/airflow/.local/lib/python3.6/site-packages/sqlalchemy/pool/base.py", line 778, in _checkout
    fairy = _ConnectionRecord.checkout(pool)
  File "/home/airflow/.local/lib/python3.6/site-packages/sqlalchemy/pool/base.py", line 495, in checkout
    rec = pool._do_get()
  File "/home/airflow/.local/lib/python3.6/site-packages/sqlalchemy/pool/impl.py", line 140, in _do_get
    self._dec_overflow()
  File "/home/airflow/.local/lib/python3.6/site-packages/sqlalchemy/util/langhelpers.py", line 70, in __exit__
    with_traceback=exc_tb,
  File "/home/airflow/.local/lib/python3.6/site-packages/sqlalchemy/util/compat.py", line 182, in raise_
    raise exception
  File "/home/airflow/.local/lib/python3.6/site-packages/sqlalchemy/pool/impl.py", line 137, in _do_get
    return self._create_connection()
  File "/home/airflow/.local/lib/python3.6/site-packages/sqlalchemy/pool/base.py", line 309, in _create_connection
    return _ConnectionRecord(self)
  File "/home/airflow/.local/lib/python3.6/site-packages/sqlalchemy/pool/base.py", line 440, in __init__
    self.__connect(first_connect_check=True)
  File "/home/airflow/.local/lib/python3.6/site-packages/sqlalchemy/pool/base.py", line 661, in __connect
    pool.logger.debug("Error on connect(): %s", e)
  File "/home/airflow/.local/lib/python3.6/site-packages/sqlalchemy/util/langhelpers.py", line 70, in __exit__
    with_traceback=exc_tb,
  File "/home/airflow/.local/lib/python3.6/site-packages/sqlalchemy/util/compat.py", line 182, in raise_
    raise exception
  File "/home/airflow/.local/lib/python3.6/site-packages/sqlalchemy/pool/base.py", line 656, in __connect
    connection = pool._invoke_creator(self)
  File "/home/airflow/.local/lib/python3.6/site-packages/sqlalchemy/engine/strategies.py", line 114, in connect
    return dialect.connect(*cargs, **cparams)
  File "/home/airflow/.local/lib/python3.6/site-packages/sqlalchemy/engine/default.py", line 508, in connect
    return self.dbapi.connect(*cargs, **cparams)
  File "/home/airflow/.local/lib/python3.6/site-packages/psycopg2/__init__.py", line 127, in connect
    conn = _connect(dsn, connection_factory=connection_factory, **kwasync)
psycopg2.OperationalError: FATAL:  database "csv_data" does not exist


The above exception was the direct cause of the following exception:

Traceback (most recent call last):
  File "/home/airflow/.local/lib/python3.6/site-packages/airflow/models/taskinstance.py", line 1112, in _run_raw_task
    self._prepare_and_execute_task_with_callbacks(context, task)
  File "/home/airflow/.local/lib/python3.6/site-packages/airflow/models/taskinstance.py", line 1285, in _prepare_and_execute_task_with_callbacks
    result = self._execute_task(context, task_copy)
  File "/home/airflow/.local/lib/python3.6/site-packages/airflow/models/taskinstance.py", line 1315, in _execute_task
    result = task_copy.execute(context=context)
  File "/home/airflow/.local/lib/python3.6/site-packages/airflow/operators/python.py", line 117, in execute
    return_value = self.execute_callable()
  File "/home/airflow/.local/lib/python3.6/site-packages/airflow/operators/python.py", line 128, in execute_callable
    return self.python_callable(*self.op_args, **self.op_kwargs)
  File "/opt/airflow/dags/csv_postgres_2_mongo.py", line 25, in _read_table_as_DF
    DF = pd.read_sql("SELECT * FROM users2021;", engine)
  File "/home/airflow/.local/lib/python3.6/site-packages/pandas/io/sql.py", line 515, in read_sql
    chunksize=chunksize,
  File "/home/airflow/.local/lib/python3.6/site-packages/pandas/io/sql.py", line 1295, in read_query
    result = self.execute(*args)
  File "/home/airflow/.local/lib/python3.6/site-packages/pandas/io/sql.py", line 1162, in execute
    *args, **kwargs
  File "/home/airflow/.local/lib/python3.6/site-packages/sqlalchemy/engine/base.py", line 2234, in execute
    connection = self._contextual_connect(close_with_result=True)
  File "/home/airflow/.local/lib/python3.6/site-packages/sqlalchemy/engine/base.py", line 2302, in _contextual_connect
    self._wrap_pool_connect(self.pool.connect, None),
  File "/home/airflow/.local/lib/python3.6/site-packages/sqlalchemy/engine/base.py", line 2340, in _wrap_pool_connect
    e, dialect, self
  File "/home/airflow/.local/lib/python3.6/site-packages/sqlalchemy/engine/base.py", line 1584, in _handle_dbapi_exception_noconnection
    sqlalchemy_exception, with_traceback=exc_info[2], from_=e
  File "/home/airflow/.local/lib/python3.6/site-packages/sqlalchemy/util/compat.py", line 182, in raise_
    raise exception
  File "/home/airflow/.local/lib/python3.6/site-packages/sqlalchemy/engine/base.py", line 2336, in _wrap_pool_connect
    return fn()
  File "/home/airflow/.local/lib/python3.6/site-packages/sqlalchemy/pool/base.py", line 364, in connect
    return _ConnectionFairy._checkout(self)
  File "/home/airflow/.local/lib/python3.6/site-packages/sqlalchemy/pool/base.py", line 778, in _checkout
    fairy = _ConnectionRecord.checkout(pool)
  File "/home/airflow/.local/lib/python3.6/site-packages/sqlalchemy/pool/base.py", line 495, in checkout
    rec = pool._do_get()
  File "/home/airflow/.local/lib/python3.6/site-packages/sqlalchemy/pool/impl.py", line 140, in _do_get
    self._dec_overflow()
  File "/home/airflow/.local/lib/python3.6/site-packages/sqlalchemy/util/langhelpers.py", line 70, in __exit__
    with_traceback=exc_tb,
  File "/home/airflow/.local/lib/python3.6/site-packages/sqlalchemy/util/compat.py", line 182, in raise_
    raise exception
  File "/home/airflow/.local/lib/python3.6/site-packages/sqlalchemy/pool/impl.py", line 137, in _do_get
    return self._create_connection()
  File "/home/airflow/.local/lib/python3.6/site-packages/sqlalchemy/pool/base.py", line 309, in _create_connection
    return _ConnectionRecord(self)
  File "/home/airflow/.local/lib/python3.6/site-packages/sqlalchemy/pool/base.py", line 440, in __init__
    self.__connect(first_connect_check=True)
  File "/home/airflow/.local/lib/python3.6/site-packages/sqlalchemy/pool/base.py", line 661, in __connect
    pool.logger.debug("Error on connect(): %s", e)
  File "/home/airflow/.local/lib/python3.6/site-packages/sqlalchemy/util/langhelpers.py", line 70, in __exit__
    with_traceback=exc_tb,
  File "/home/airflow/.local/lib/python3.6/site-packages/sqlalchemy/util/compat.py", line 182, in raise_
    raise exception
  File "/home/airflow/.local/lib/python3.6/site-packages/sqlalchemy/pool/base.py", line 656, in __connect
    connection = pool._invoke_creator(self)
  File "/home/airflow/.local/lib/python3.6/site-packages/sqlalchemy/engine/strategies.py", line 114, in connect
    return dialect.connect(*cargs, **cparams)
  File "/home/airflow/.local/lib/python3.6/site-packages/sqlalchemy/engine/default.py", line 508, in connect
    return self.dbapi.connect(*cargs, **cparams)
  File "/home/airflow/.local/lib/python3.6/site-packages/psycopg2/__init__.py", line 127, in connect
    conn = _connect(dsn, connection_factory=connection_factory, **kwasync)
sqlalchemy.exc.OperationalError: (psycopg2.OperationalError) FATAL:  database "csv_data" does not exist

(Background on this error at: http://sqlalche.me/e/13/e3q8)
[2021-05-17 07:19:58,094] {taskinstance.py:1503} INFO - Marking task as FAILED. dag_id=etl_postgresql2mongo, task_id=read_table_as_DF, execution_date=20210517T071000, start_date=20210517T071957, end_date=20210517T071958
[2021-05-17 07:19:58,162] {local_task_job.py:146} INFO - Task exited with return code 1
